Workbook

Sheet 8月白班及加班统计
A1: 2026年8月考勤明细表（白班封顶12h/天，超出计加班；明细补卡后本表自动重算）
A2: 姓名 | B2: 上班天数 | C2: 白班 | D2: 加班 | E2: 合计 | G2: 姓名 | H2: 上班天数 | I2: 白班 | J2: 加班 | K2: 合计
A3: 杨秀联 | B3: =IF(COUNTIFS('每日明细'!$A$2:$A$1892,$A3,'每日明细'!$G$2:$G$1892,"正常")=0,"/",COUNTIFS('每日明细'!$A$2:$A$1892,$A3,'每日明细'!$G$2:$G$1892,"正常")) | C3: =IF($B3="/","/",SUMIFS('每日明细'!$K$2:$K$1892,'每日明细'!$A$2:$A$1892,$A3)) | D3: =IF($B3="/","/",SUMIFS('每日明细'!$L$2:$L$1892,'每日明细'!$A$2:$A$1892,$A3)) | E3: =IF($B3="/","/",$C3+$D3) | G3: 张恩兵 | H3: =IF(COUNTIFS('每日明细'!$A$2:$A$1892,$G3,'每日明细'!$G$2:$G$1892,"正常")=0,"/",COUNTIFS('每日明细'!$A$2:$A$1892,$G3,'每日明细'!$G$2:$G$1892,"正常")) | I3: =IF($H3="/","/",SUMIFS('每日明细'!$K$2:$K$1892,'每日明细'!$A$2:$A$1892,$G3)) | J3: =IF($H3="/","/",SUMIFS('每日明细'!$L$2:$L$1892,'每日明细'!$A$2:$A$1892,$G3)) | K3: =IF($H3="/","/",$I3+$J3)
A4: 宋龙元 | B4: =IF(COUNTIFS('每日明细'!$A$2:$A$1892,$A4,'每日明细'!$G$2:$G$1892,"正常")=0,"/",COUNTIFS('每日明细'!$A$2:$A$1892,$A4,'每日明细'!$G$2:$G$1892,"正常")) | C4: =IF($B4="/","/",SUMIFS('每日明细'!$K$2:$K$1892,'每日明细'!$A$2:$A$1892,$A4)) | D4: =IF($B4="/","/",SUMIFS('每日明细'!$L$2:$L$1892,'每日明细'!$A$2:$A$1892,$A4)) | E4: =IF($B4="/","/",$C4+$D4) | G4: 何开伦 | H4: =IF(COUNTIFS('每日明细'!$A$2:$A$1892,$G4,'每日明细'!$G$2:$G$1892,"正常")=0,"/",COUNTIFS('每日明细'!$A$2:$A$1892,$G4,'每日明细'!$G$2:$G$1892,"正常")) | I4: =IF($H4="/","/",SUMIFS('每日明细'!$K$2:$K$1892,'每日明细'!$A$2:$A$1892,$G4)) | J4: =IF($H4="/","/",SUMIFS('每日明细'!$L$2:$L$1892,'每日明细'!$A$2:$A$1892,$G4)) | K4: =IF($H4="/","/",$I4+$J4)
A5: 李露 | B5: =IF(COUNTIFS('每日明细'!$A$2:$A$1892,$A5,'每日明细'!$G$2:$G$1892,"正常")=0,"/",COUNTIFS('每日明细'!$A$2:$A$1892,$A5,'每日明细'!$G$2:$G$1892,"正常")) | C5: =IF($B5="/","/",SUMIFS('每日明细'!$K$2:$K$1892,'每日明细'!$A$2:$A$1892,$A5)) | D5: =IF($B5="/","/",SUMIFS('每日明细'!$L$2:$L$1892,'每日明细'!$A$2:$A$1892,$A5)) | E5: =IF($B5="/","/",$C5+$D5) | G5: 李小俐 | H5: =IF(COUNTIFS('每日明细'!$A$2:$A$1892,$G5,'每日明细'!$G$2:$G$1892,"正常")=0,"/",COUNTIFS('每日明细'!$A$2:$A$1892,$G5,'每日明细'!$G$2:$G$1892,"正常")) | I5: =IF($H5="/","/",SUMIFS('每日明细'!$K$2:$K$1892,'每日明细'!$A$2:$A$1892,$G5)) | J5: =IF($H5="/","/",SUMIFS('每日明细'!$L$2:$L$1892,'每日明细'!$A$2:$A$1892,$G5)) | K5: =IF($H5="/","/",$I5+$J5)
A6: 熊其容 | B6: =IF(COUNTIFS('每日明细'!$A$2:$A$1892,$A6,'每日明细'!$G$2:$G$1892,"正常")=0,"/",COUNTIFS('每日明细'!$A$2:$A$1892,$A6,'每日明细'!$G$2:$G$1892,"正常")) | C6: =IF($B6="/","/",SUMIFS('每日明细'!$K$2:$K$1892,'每日明细'!$A$2:$A$1892,$A6)) | D6: =IF($B6="/","/",SUMIFS('每日明细'!$L$2:$L$1892,'每日明细'!$A$2:$A$1892,$A6)) | E6: =IF($B6="/","/",$C6+$D6) | G6: 李厚强 | H6: =IF(COUNTIFS('每日明细'!$A$2:$A$1892,$G6,'每日明细'!$G$2:$G$1892,"正常")=0,"/",COUNTIFS('每日明细'!$A$2:$A$1892,$G6,'每日明细'!$G$2:$G$1892,"正常")) | I6: =IF($H6="/","/",SUMIFS('每日明细'!$K$2:$K$1892,'每日明细'!$A$2:$A$1892,$G6)) | J6: =IF($H6="/","/",SUMIFS('每日明细'!$L$2:$L$1892,'每日明细'!$A$2:$A$1892,$G6)) | K6: =IF($H6="/","/",$I6+$J6)
A7: 范云 | B7: =IF(COUNTIFS('每日明细'!$A$2:$A$1892,$A7,'每日明细'!$G$2:$G$1892,"正常")=0,"/",COUNTIFS('每日明细'!$A$2:$A$1892,$A7,'每日明细'!$G$2:$G$1892,"正常")) | C7: =IF($B7="/","/",SUMIFS('每日明细'!$K$2:$K$1892,'每日明细'!$A$2:$A$1892,$A7)) | D7: =IF($B7="/","/",SUMIFS('每日明细'!$L$2:$L$1892,'每日明细'!$A$2:$A$1892,$A7)) | E7: =IF($B7="/","/",$C7+$D7) | G7: 刘常谦 | H7: =IF(COUNTIFS('每日明细'!$A$2:$A$1892,$G7,'每日明细'!$G$2:$G$1892,"正常")=0,"/",COUNTIFS('每日明细'!$A$2:$A$1892,$G7,'每日明细'!$G$2:$G$1892,"正常")) | I7: =IF($H7="/","/",SUMIFS('每日明细'!$K$2:$K$1892,'每日明细'!$A$2:$A$1892,$G7)) | J7: =IF($H7="/","/",SUMIFS('每日明细'!$L$2:$L$1892,'每日明细'!$A$2:$A$1892,$G7)) | K7: =IF($H7="/","/",$I7+$J7)
A8: 沈学富 | B8: =IF(COUNTIFS('每日明细'!$A$2:$A$1892,$A8,'每日明细'!$G$2:$G$1892,"正常")=0,"/",COUNTIFS('每日明细'!$A$2:$A$1892,$A8,'每日明细'!$G$2:$G$1892,"正常")) | C8: =IF($B8="/","/",SUMIFS('每日明细'!$K$2:$K$1892,'每日明细'!$A$2:$A$1892,$A8)) | D8: =IF($B8="/","/",SUMIFS('每日明细'!$L$2:$L$1892,'每日明细'!$A$2:$A$1892,$A8)) | E8: =IF($B8="/","/",$C8+$D8) | G8: 王召会 | H8: =IF(COUNTIFS('每日明细'!$A$2:$A$1892,$G8,'每日明细'!$G$2:$G$1892,"正常")=0,"/",COUNTIFS('每日明细'!$A$2:$A$1892,$G8,'每日明细'!$G$2:$G$1892,"正常")) | I8: =IF($H8="/","/",SUMIFS('每日明细'!$K$2:$K$1892,'每日明细'!$A$2:$A$1892,$G8)) | J8: =IF($H8="/","/",SUMIFS('每日明细'!$L$2:$L$1892,'每日明细'!$A$2:$A$1892,$G8)) | K8: =IF($H8="/","/",$I8+$J8)
A9: 曾德双 | B9: =IF(COUNTIFS('每日明细'!$A$2:$A$1892,$A9,'每日明细'!$G$2:$G$1892,"正常")=0,"/",COUNTIFS('每日明细'!$A$2:$A$1892,$A9,'每日明细'!$G$2:$G$1892,"正常")) | C9: =IF($B9="/","/",SUMIFS('每日明细'!$K$2:$K$1892,'每日明细'!$A$2:$A$1892,$A9)) | D9: =IF($B9="/","/",SUMIFS('每日明细'!$L$2:$L$1892,'每日明细'!$A$2:$A$1892,$A9)) | E9: =IF($B9="/","/",$C9+$D9) | G9: 岳安容 | H9: =IF(COUNTIFS('每日明细'!$A$2:$A$1892,$G9,'每日明细'!$G$2:$G$1892,"正常")=0,"/",COUNTIFS('每日明细'!$A$2:$A$1892,$G9,'每日明细'!$G$2:$G$1892,"正常")) | I9: =IF($H9="/","/",SUMIFS('每日明细'!$K$2:$K$1892,'每日明细'!$A$2:$A$1892,$G9)) | J9: =IF($H9="/","/",SUMIFS('每日明细'!$L$2:$L$1892,'每日明细'!$A$2:$A$1892,$G9)) | K9: =IF($H9="/","/",$I9+$J9)
A10: 喻碧 | B10: =IF(COUNTIFS('每日明细'!$A$2:$A$1892,$A10,'每日明细'!$G$2:$G$1892,"正常")=0,"/",COUNTIFS('每日明细'!$A$2:$A$1892,$A10,'每日明细'!$G$2:$G$1892,"正常")) | C10: =IF($B10="/","/",SUMIFS('每日明细'!$K$2:$K$1892,'每日明细'!$A$2:$A$1892,$A10)) | D10: =IF($B10="/","/",SUMIFS('每日明细'!$L$2:$L$1892,'每日明细'!$A$2:$A$1892,$A10)) | E10: =IF($B10="/","/",$C10+$D10) | G10: 陈善芳 | H10: =IF(COUNTIFS('每日明细'!$A$2:$A$1892,$G10,'每日明细'!$G$2:$G$1892,"正常")=0,"/",COUNTIFS('每日明细'!$A$2:$A$1892,$G10,'每日明细'!$G$2:$G$1892,"正常")) | I10: =IF($H10="/","/",SUMIFS('每日明细'!$K$2:$K$1892,'每日明细'!$A$2:$A$1892,$G10)) | J10: =IF($H10="/","/",SUMIFS('每日明细'!$L$2:$L$1892,'每日明细'!$A$2:$A$1892,$G10)) | K10: =IF($H10="/","/",$I10+$J10)
A11: 董世会 | B11: =IF(COUNTIFS('每日明细'!$A$2:$A$1892,$A11,'每日明细'!$G$2:$G$1892,"正常")=0,"/",COUNTIFS('每日明细'!$A$2:$A$1892,$A11,'每日明细'!$G$2:$G$1892,"正常")) | C11: =IF($B11="/","/",SUMIFS('每日明细'!$K$2:$K$1892,'每日明细'!$A$2:$A$1892,$A11)) | D11: =IF($B11="/","/",SUMIFS('每日明细'!$L$2:$L$1892,'每日明细'!$A$2:$A$1892,$A11)) | E11: =IF($B11="/","/",$C11+$D11) | G11: 钟富菊 | H11: =IF(COUNTIFS('每日明细'!$A$2:$A$1892,$G11,'每日明细'!$G$2:$G$1892,"正常")=0,"/",COUNTIFS('每日明细'!$A$2:$A$1892,$G11,'每日明细'!$G$2:$G$1892,"正常")) | I11: =IF($H11="/","/",SUMIFS('每日明细'!$K$2:$K$1892,'每日明细'!$A$2:$A$1892,$G11)) | J11: =IF($H11="/","/",SUMIFS('每日明细'!$L$2:$L$1892,'每日明细'!$A$2:$A$1892,$G11)) | K11: =IF($H11="/","/",$I11+$J11)
A12: 蹇泽会 | B12: =IF(COUNTIFS('每日明细'!$A$2:$A$1892,$A12,'每日明细'!$G$2:$G$1892,"正常")=0,"/",COUNTIFS('每日明细'!$A$2:$A$1892,$A12,'每日明细'!$G$2:$G$1892,"正常")) | C12: =IF($B12="/","/",SUMIFS('每日明细'!$K$2:$K$1892,'每日明细'!$A$2:$A$1892,$A12)) | D12: =IF($B12="/","/",SUMIFS('每日明细'!$L$2:$L$1892,'每日明细'!$A$2:$A$1892,$A12)) | E12: =IF($B12="/","/",$C12+$D12) | G12: 吴光德 | H12: =IF(COUNTIFS('每日明细'!$A$2:$A$1892,$G12,'每日明细'!$G$2:$G$1892,"正常")=0,"/",COUNTIFS('每日明细'!$A$2:$A$1892,$G12,'每日明细'!$G$2:$G$1892,"正常")) | I12: =IF($H12="/","/",SUMIFS('每日明细'!$K$2:$K$1892,'每日明细'!$A$2:$A$1892,$G12)) | J12: =IF($H12="/","/",SUMIFS('每日明细'!$L$2:$L$1892,'每日明细'!$A$2:$A$1892,$G12)) | K12: =IF($H12="/","/",$I12+$J12)
A13: 沈俊维 | B13: =IF(COUNTIFS('每日明细'!$A$2:$A$1892,$A13,'每日明细'!$G$2:$G$1892,"正常")=0,"/",COUNTIFS('每日明细'!$A$2:$A$1892,$A13,'每日明细'!$G$2:$G$1892,"正常")) | C13: =IF($B13="/","/",SUMIFS('每日明细'!$K$2:$K$1892,'每日明细'!$A$2:$A$1892,$A13)) | D13: =IF($B13="/","/",SUMIFS('每日明细'!$L$2:$L$1892,'每日明细'!$A$2:$A$1892,$A13)) | E13: =IF($B13="/","/",$C13+$D13) | G13: 王林维 | H13: =IF(COUNTIFS('每日明细'!$A$2:$A$1892,$G13,'每日明细'!$G$2:$G$1892,"正常")=0,"/",COUNTIFS('每日明细'!$A$2:$A$1892,$G13,'每日明细'!$G$2:$G$1892,"正常")) | I13: =IF($H13="/","/",SUMIFS('每日明细'!$K$2:$K$1892,'每日明细'!$A$2:$A$1892,$G13)) | J13: =IF($H13="/","/",SUMIFS('每日明细'!$L$2:$L$1892,'每日明细'!$A$2:$A$1892,$G13)) | K13: =IF($H13="/","/",$I13+$J13)
A14: 杨金玉 | B14: =IF(COUNTIFS('每日明细'!$A$2:$A$1892,$A14,'每日明细'!$G$2:$G$1892,"正常")=0,"/",COUNTIFS('每日明细'!$A$2:$A$1892,$A14,'每日明细'!$G$2:$G$1892,"正常")) | C14: =IF($B14="/","/",SUMIFS('每日明细'!$K$2:$K$1892,'每日明细'!$A$2:$A$1892,$A14)) | D14: =IF($B14="/","/",SUMIFS('每日明细'!$L$2:$L$1892,'每日明细'!$A$2:$A$1892,$A14)) | E14: =IF($B14="/","/",$C14+$D14) | G14: 李树梅 | H14: =IF(COUNTIFS('每日明细'!$A$2:$A$1892,$G14,'每日明细'!$G$2:$G$1892,"正常")=0,"/",COUNTIFS('每日明细'!$A$2:$A$1892,$G14,'每日明细'!$G$2:$G$1892,"正常")) | I14: =IF($H14="/","/",SUMIFS('每日明细'!$K$2:$K$1892,'每日明细'!$A$2:$A$1892,$G14)) | J14: =IF($H14="/","/",SUMIFS('每日明细'!$L$2:$L$1892,'每日明细'!$A$2:$A$1892,$G14)) | K14: =IF($H14="/","/",$I14+$J14)
... A32: 曾德秀 | B32: =IF(COUNTIFS('每日明细'!$A$2:$A$1892,$A32,'每日明细'!$G$2:$G$1892,"正常")=0,"/",COUNTIFS('每日明细'!$A$2:$A$1892,$A32,'每日明细'!$G$2:$G$1892,"正常")) | C32: =IF($B32="/","/",SUMIFS('每日明细'!$K$2:$K$1892,'每日明细'!$A$2:$A$1892,$A32)) | D32: =IF($B32="/","/",SUMIFS('每日明细'!$L$2:$L$1892,'每日明细'!$A$2:$A$1892,$A32)) | E32: =IF($B32="/","/",$C32+$D32) | G32: 黎应菊 | H32: =IF(COUNTIFS('每日明细'!$A$2:$A$1892,$G32,'每日明细'!$G$2:$G$1892,"正常")=0,"/",COUNTIFS('每日明细'!$A$2:$A$1892,$G32,'每日明细'!$G$2:$G$1892,"正常")) | I32: =IF($H32="/","/",SUMIFS('每日明细'!$K$2:$K$1892,'每日明细'!$A$2:$A$1892,$G32)) | J32: =IF($H32="/","/",SUMIFS('每日明细'!$L$2:$L$1892,'每日明细'!$A$2:$A$1892,$G32)) | K32: =IF($H32="/","/",$I32+$J32)
A33: 杨泽菊 | B33: =IF(COUNTIFS('每日明细'!$A$2:$A$1892,$A33,'每日明细'!$G$2:$G$1892,"正常")=0,"/",COUNTIFS('每日明细'!$A$2:$A$1892,$A33,'每日明细'!$G$2:$G$1892,"正常")) | C33: =IF($B33="/","/",SUMIFS('每日明细'!$K$2:$K$1892,'每日明细'!$A$2:$A$1892,$A33)) | D33: =IF($B33="/","/",SUMIFS('每日明细'!$L$2:$L$1892,'每日明细'!$A$2:$A$1892,$A33)) | E33: =IF($B33="/","/",$C33+$D33)

Sheet 每日明细
A1: 姓名 | B1: 日期 | C1: 星期 | D1: 当日打卡 | E1: 首卡 | F1: 末卡 | G1: 状态 | H1: 跨度(分钟) | I1: 跨度(h) | J1: 取整工时 | K1: 白班 | L1: 加班
A2: 杨秀联 | B2: 8/1 | C2: 六 | D2: 07:58 17:02 | E2: 0.33194444 | F2: 0.70972222 | G2: =IF($E2="","空卡",IF($F2="","单卡","正常")) | H2: =IF($G2="正常",ROUND(($F2-$E2)*1440,0),"") | I2: =IF($G2="正常",$H2/60,"") | J2: =IF($G2="正常",ROUND($H2/30,0)/2,"") | K2: =IF($G2="正常",MIN($J2,12),"") | L2: =IF($G2="正常",MAX($J2-12,0),"")
A3: 杨秀联 | B3: 8/2 | C3: 日 | D3: 07:57 | E3: 0.33125 | G3: =IF($E3="","空卡",IF($F3="","单卡","正常")) | H3: =IF($G3="正常",ROUND(($F3-$E3)*1440,0),"") | I3: =IF($G3="正常",$H3/60,"") | J3: =IF($G3="正常",ROUND($H3/30,0)/2,"") | K3: =IF($G3="正常",MIN($J3,12),"") | L3: =IF($G3="正常",MAX($J3-12,0),"")
A4: 杨秀联 | B4: 8/3 | C4: 一 | D4: 08:27 15:36 | E4: 0.35208333 | F4: 0.65 | G4: =IF($E4="","空卡",IF($F4="","单卡","正常")) | H4: =IF($G4="正常",ROUND(($F4-$E4)*1440,0),"") | I4: =IF($G4="正常",$H4/60,"") | J4: =IF($G4="正常",ROUND($H4/30,0)/2,"") | K4: =IF($G4="正常",MIN($J4,12),"") | L4: =IF($G4="正常",MAX($J4-12,0),"")
A5: 杨秀联 | B5: 8/4 | C5: 二 | G5: =IF($E5="","空卡",IF($F5="","单卡","正常")) | H5: =IF($G5="正常",ROUND(($F5-$E5)*1440,0),"") | I5: =IF($G5="正常",$H5/60,"") | J5: =IF($G5="正常",ROUND($H5/30,0)/2,"") | K5: =IF($G5="正常",MIN($J5,12),"") | L5: =IF($G5="正常",MAX($J5-12,0),"")
A6: 杨秀联 | B6: 8/5 | C6: 三 | D6: 09:58 19:58 | E6: 0.41527778 | F6: 0.83194444 | G6: =IF($E6="","空卡",IF($F6="","单卡","正常")) | H6: =IF($G6="正常",ROUND(($F6-$E6)*1440,0),"") | I6: =IF($G6="正常",$H6/60,"") | J6: =IF($G6="正常",ROUND($H6/30,0)/2,"") | K6: =IF($G6="正常",MIN($J6,12),"") | L6: =IF($G6="正常",MAX($J6-12,0),"")
A7: 杨秀联 | B7: 8/6 | C7: 四 | D7: 08:53 20:01 | E7: 0.37013889 | F7: 0.83402778 | G7: =IF($E7="","空卡",IF($F7="","单卡","正常")) | H7: =IF($G7="正常",ROUND(($F7-$E7)*1440,0),"") | I7: =IF($G7="正常",$H7/60,"") | J7: =IF($G7="正常",ROUND($H7/30,0)/2,"") | K7: =IF($G7="正常",MIN($J7,12),"") | L7: =IF($G7="正常",MAX($J7-12,0),"")
A8: 杨秀联 | B8: 8/7 | C8: 五 | D8: 07:53 20:02 | E8: 0.32847222 | F8: 0.83472222 | G8: =IF($E8="","空卡",IF($F8="","单卡","正常")) | H8: =IF($G8="正常",ROUND(($F8-$E8)*1440,0),"") | I8: =IF($G8="正常",$H8/60,"") | J8: =IF($G8="正常",ROUND($H8/30,0)/2,"") | K8: =IF($G8="正常",MIN($J8,12),"") | L8: =IF($G8="正常",MAX($J8-12,0),"")
A9: 杨秀联 | B9: 8/8 | C9: 六 | G9: =IF($E9="","空卡",IF($F9="","单卡","正常")) | H9: =IF($G9="正常",ROUND(($F9-$E9)*1440,0),"") | I9: =IF($G9="正常",$H9/60,"") | J9: =IF($G9="正常",ROUND($H9/30,0)/2,"") | K9: =IF($G9="正常",MIN($J9,12),"") | L9: =IF($G9="正常",MAX($J9-12,0),"")
A10: 杨秀联 | B10: 8/9 | C10: 日 | G10: =IF($E10="","空卡",IF($F10="","单卡","正常")) | H10: =IF($G10="正常",ROUND(($F10-$E10)*1440,0),"") | I10: =IF($G10="正常",$H10/60,"") | J10: =IF($G10="正常",ROUND($H10/30,0)/2,"") | K10: =IF($G10="正常",MIN($J10,12),"") | L10: =IF($G10="正常",MAX($J10-12,0),"")
A11: 杨秀联 | B11: 8/10 | C11: 一 | D11: 08:24 19:56 | E11: 0.35 | F11: 0.83055556 | G11: =IF($E11="","空卡",IF($F11="","单卡","正常")) | H11: =IF($G11="正常",ROUND(($F11-$E11)*1440,0),"") | I11: =IF($G11="正常",$H11/60,"") | J11: =IF($G11="正常",ROUND($H11/30,0)/2,"") | K11: =IF($G11="正常",MIN($J11,12),"") | L11: =IF($G11="正常",MAX($J11-12,0),"")
A12: 杨秀联 | B12: 8/11 | C12: 二 | D12: 08:27 18:08 | E12: 0.35208333 | F12: 0.75555556 | G12: =IF($E12="","空卡",IF($F12="","单卡","正常")) | H12: =IF($G12="正常",ROUND(($F12-$E12)*1440,0),"") | I12: =IF($G12="正常",$H12/60,"") | J12: =IF($G12="正常",ROUND($H12/30,0)/2,"") | K12: =IF($G12="正常",MIN($J12,12),"") | L12: =IF($G12="正常",MAX($J12-12,0),"")
A13: 杨秀联 | B13: 8/12 | C13: 三 | D13: 08:24 18:38 | E13: 0.35 | F13: 0.77638889 | G13: =IF($E13="","空卡",IF($F13="","单卡","正常")) | H13: =IF($G13="正常",ROUND(($F13-$E13)*1440,0),"") | I13: =IF($G13="正常",$H13/60,"") | J13: =IF($G13="正常",ROUND($H13/30,0)/2,"") | K13: =IF($G13="正常",MIN($J13,12),"") | L13: =IF($G13="正常",MAX($J13-12,0),"")
A14: 杨秀联 | B14: 8/13 | C14: 四 | D14: 09:59 19:06 | E14: 0.41597222 | F14: 0.79583333 | G14: =IF($E14="","空卡",IF($F14="","单卡","正常")) | H14: =IF($G14="正常",ROUND(($F14-$E14)*1440,0),"") | I14: =IF($G14="正常",$H14/60,"") | J14: =IF($G14="正常",ROUND($H14/30,0)/2,"") | K14: =IF($G14="正常",MIN($J14,12),"") | L14: =IF($G14="正常",MAX($J14-12,0),"")
A15: 杨秀联 | B15: 8/14 | C15: 五 | D15: 06:58 21:04 | E15: 0.29027778 | F15: 0.87777778 | G15: =IF($E15="","空卡",IF($F15="","单卡","正常")) | H15: =IF($G15="正常",ROUND(($F15-$E15)*1440,0),"") | I15: =IF($G15="正常",$H15/60,"") | J15: =IF($G15="正常",ROUND($H15/30,0)/2,"") | K15: =IF($G15="正常",MIN($J15,12),"") | L15: =IF($G15="正常",MAX($J15-12,0),"")
A16: 杨秀联 | B16: 8/15 | C16: 六 | D16: 06:57 19:01 | E16: 0.28958333 | F16: 0.79236111 | G16: =IF($E16="","空卡",IF($F16="","单卡","正常")) | H16: =IF($G16="正常",ROUND(($F16-$E16)*1440,0),"") | I16: =IF($G16="正常",$H16/60,"") | J16: =IF($G16="正常",ROUND($H16/30,0)/2,"") | K16: =IF($G16="正常",MIN($J16,12),"") | L16: =IF($G16="正常",MAX($J16-12,0),"")
A17: 杨秀联 | B17: 8/16 | C17: 日 | G17: =IF($E17="","空卡",IF($F17="","单卡","正常")) | H17: =IF($G17="正常",ROUND(($F17-$E17)*1440,0),"") | I17: =IF($G17="正常",$H17/60,"") | J17: =IF($G17="正常",ROUND($H17/30,0)/2,"") | K17: =IF($G17="正常",MIN($J17,12),"") | L17: =IF($G17="正常",MAX($J17-12,0),"")
A18: 杨秀联 | B18: 8/17 | C18: 一 | D18: 07:55 20:06 | E18: 0.32986111 | F18: 0.8375 | G18: =IF($E18="","空卡",IF($F18="","单卡","正常")) | H18: =IF($G18="正常",ROUND(($F18-$E18)*1440,0),"") | I18: =IF($G18="正常",$H18/60,"") | J18: =IF($G18="正常",ROUND($H18/30,0)/2,"") | K18: =IF($G18="正常",MIN($J18,12),"") | L18: =IF($G18="正常",MAX($J18-12,0),"")
A19: 杨秀联 | B19: 8/18 | C19: 二 | D19: 07:55 18:57 | E19: 0.32986111 | F19: 0.78958333 | G19: =IF($E19="","空卡",IF($F19="","单卡","正常")) | H19: =IF($G19="正常",ROUND(($F19-$E19)*1440,0),"") | I19: =IF($G19="正常",$H19/60,"") | J19: =IF($G19="正常",ROUND($H19/30,0)/2,"") | K19: =IF($G19="正常",MIN($J19,12),"") | L19: =IF($G19="正常",MAX($J19-12,0),"")
A20: 杨秀联 | B20: 8/19 | C20: 三 | D20: 08:58 20:32 | E20: 0.37361111 | F20: 0.85555556 | G20: =IF($E20="","空卡",IF($F20="","单卡","正常")) | H20: =IF($G20="正常",ROUND(($F20-$E20)*1440,0),"") | I20: =IF($G20="正常",$H20/60,"") | J20: =IF($G20="正常",ROUND($H20/30,0)/2,"") | K20: =IF($G20="正常",MIN($J20,12),"") | L20: =IF($G20="正常",MAX($J20-12,0),"")
A21: 杨秀联 | B21: 8/20 | C21: 四 | D21: 08:31 20:02 | E21: 0.35486111 | F21: 0.83472222 | G21: =IF($E21="","空卡",IF($F21="","单卡","正常")) | H21: =IF($G21="正常",ROUND(($F21-$E21)*1440,0),"") | I21: =IF($G21="正常",$H21/60,"") | J21: =IF($G21="正常",ROUND($H21/30,0)/2,"") | K21: =IF($G21="正常",MIN($J21,12),"") | L21: =IF($G21="正常",MAX($J21-12,0),"")
A22: 杨秀联 | B22: 8/21 | C22: 五 | D22: 06:58 19:03 | E22: 0.29027778 | F22: 0.79375 | G22: =IF($E22="","空卡",IF($F22="","单卡","正常")) | H22: =IF($G22="正常",ROUND(($F22-$E22)*1440,0),"") | I22: =IF($G22="正常",$H22/60,"") | J22: =IF($G22="正常",ROUND($H22/30,0)/2,"") | K22: =IF($G22="正常",MIN($J22,12),"") | L22: =IF($G22="正常",MAX($J22-12,0),"")
A23: 杨秀联 | B23: 8/22 | C23: 六 | D23: 06:58 17:31 | E23: 0.29027778 | F23: 0.72986111 | G23: =IF($E23="","空卡",IF($F23="","单卡","正常")) | H23: =IF($G23="正常",ROUND(($F23-$E23)*1440,0),"") | I23: =IF($G23="正常",$H23/60,"") | J23: =IF($G23="正常",ROUND($H23/30,0)/2,"") | K23: =IF($G23="正常",MIN($J23,12),"") | L23: =IF($G23="正常",MAX($J23-12,0),"")
A24: 杨秀联 | B24: 8/23 | C24: 日 | G24: =IF($E24="","空卡",IF($F24="","单卡","正常")) | H24: =IF($G24="正常",ROUND(($F24-$E24)*1440,0),"") | I24: =IF($G24="正常",$H24/60,"") | J24: =IF($G24="正常",ROUND($H24/30,0)/2,"") | K24: =IF($G24="正常",MIN($J24,12),"") | L24: =IF($G24="正常",MAX($J24-12,0),"")
A25: 杨秀联 | B25: 8/24 | C25: 一 | D25: 06:58 17:03 | E25: 0.29027778 | F25: 0.71041667 | G25: =IF($E25="","空卡",IF($F25="","单卡","正常")) | H25: =IF($G25="正常",ROUND(($F25-$E25)*1440,0),"") | I25: =IF($G25="正常",$H25/60,"") | J25: =IF($G25="正常",ROUND($H25/30,0)/2,"") | K25: =IF($G25="正常",MIN($J25,12),"") | L25: =IF($G25="正常",MAX($J25-12,0),"")
A26: 杨秀联 | B26: 8/25 | C26: 二 | D26: 07:58 18:37 | E26: 0.33194444 | F26: 0.77569444 | G26: =IF($E26="","空卡",IF($F26="","单卡","正常")) | H26: =IF($G26="正常",ROUND(($F26-$E26)*1440,0),"") | I26: =IF($G26="正常",$H26/60,"") | J26: =IF($G26="正常",ROUND($H26/30,0)/2,"") | K26: =IF($G26="正常",MIN($J26,12),"") | L26: =IF($G26="正常",MAX($J26-12,0),"")
A27: 杨秀联 | B27: 8/26 | C27: 三 | D27: 07:57 18:58 | E27: 0.33125 | F27: 0.79027778 | G27: =IF($E27="","空卡",IF($F27="","单卡","正常")) | H27: =IF($G27="正常",ROUND(($F27-$E27)*1440,0),"") | I27: =IF($G27="正常",$H27/60,"") | J27: =IF($G27="正常",ROUND($H27/30,0)/2,"") | K27: =IF($G27="正常",MIN($J27,12),"") | L27: =IF($G27="正常",MAX($J27-12,0),"")
A28: 杨秀联 | B28: 8/27 | C28: 四 | D28: 07:56 21:02 | E28: 0.33055556 | F28: 0.87638889 | G28: =IF($E28="","空卡",IF($F28="","单卡","正常")) | H28: =IF($G28="正常",ROUND(($F28-$E28)*1440,0),"") | I28: =IF($G28="正常",$H28/60,"") | J28: =IF($G28="正常",ROUND($H28/30,0)/2,"") | K28: =IF($G28="正常",MIN($J28,12),"") | L28: =IF($G28="正常",MAX($J28-12,0),"")
A29: 杨秀联 | B29: 8/28 | C29: 五 | D29: 07:57 21:03 | E29: 0.33125 | F29: 0.87708333 | G29: =IF($E29="","空卡",IF($F29="","单卡","正常")) | H29: =IF($G29="正常",ROUND(($F29-$E29)*1440,0),"") | I29: =IF($G29="正常",$H29/60,"") | J29: =IF($G29="正常",ROUND($H29/30,0)/2,"") | K29: =IF($G29="正常",MIN($J29,12),"") | L29: =IF($G29="正常",MAX($J29-12,0),"")
A30: 杨秀联 | B30: 8/29 | C30: 六 | D30: 07:57 22:34 | E30: 0.33125 | F30: 0.94027778 | G30: =IF($E30="","空卡",IF($F30="","单卡","正常")) | H30: =IF($G30="正常",ROUND(($F30-$E30)*1440,0),"") | I30: =IF($G30="正常",$H30/60,"") | J30: =IF($G30="正常",ROUND($H30/30,0)/2,"") | K30: =IF($G30="正常",MIN($J30,12),"") | L30: =IF($G30="正常",MAX($J30-12,0),"")
A31: 杨秀联 | B31: 8/30 | C31: 日 | D31: 07:55 18:44 | E31: 0.32986111 | F31: 0.78055556 | G31: =IF($E31="","空卡",IF($F31="","单卡","正常")) | H31: =IF($G31="正常",ROUND(($F31-$E31)*1440,0),"") | I31: =IF($G31="正常",$H31/60,"") | J31: =IF($G31="正常",ROUND($H31/30,0)/2,"") | K31: =IF($G31="正常",MIN($J31,12),"") | L31: =IF($G31="正常",MAX($J31-12,0),"")
A32: 杨秀联 | B32: 8/31 | C32: 一 | G32: =IF($E32="","空卡",IF($F32="","单卡","正常")) | H32: =IF($G32="正常",ROUND(($F32-$E32)*1440,0),"") | I32: =IF($G32="正常",$H32/60,"") | J32: =IF($G32="正常",ROUND($H32/30,0)/2,"") | K32: =IF($G32="正常",MIN($J32,12),"") | L32: =IF($G32="正常",MAX($J32-12,0),"")
A33: 宋龙元 | B33: 8/1 | C33: 六 | D33: 07:57 17:01 | E33: 0.33125 | F33: 0.70902778 | G33: =IF($E33="","空卡",IF($F33="","单卡","正常")) | H33: =IF($G33="正常",ROUND(($F33-$E33)*1440,0),"") | I33: =IF($G33="正常",$H33/60,"") | J33: =IF($G33="正常",ROUND($H33/30,0)/2,"") | K33: =IF($G33="正常",MIN($J33,12),"") | L33: =IF($G33="正常",MAX($J33-12,0),"")
A34: 宋龙元 | B34: 8/2 | C34: 日 | D34: 07:57 15:00 | E34: 0.33125 | F34: 0.625 | G34: =IF($E34="","空卡",IF($F34="","单卡","正常")) | H34: =IF($G34="正常",ROUND(($F34-$E34)*1440,0),"") | I34: =IF($G34="正常",$H34/60,"") | J34: =IF($G34="正常",ROUND($H34/30,0)/2,"") | K34: =IF($G34="正常",MIN($J34,12),"") | L34: =IF($G34="正常",MAX($J34-12,0),"")
A35: 宋龙元 | B35: 8/3 | C35: 一 | D35: 08:27 15:36 | E35: 0.35208333 | F35: 0.65 | G35: =IF($E35="","空卡",IF($F35="","单卡","正常")) | H35: =IF($G35="正常",ROUND(($F35-$E35)*1440,0),"") | I35: =IF($G35="正常",$H35/60,"") | J35: =IF($G35="正常",ROUND($H35/30,0)/2,"") | K35: =IF($G35="正常",MIN($J35,12),"") | L35: =IF($G35="正常",MAX($J35-12,0),"")
A36: 宋龙元 | B36: 8/4 | C36: 二 | D36: 08:57 19:31 | E36: 0.37291667 | F36: 0.81319444 | G36: =IF($E36="","空卡",IF($F36="","单卡","正常")) | H36: =IF($G36="正常",ROUND(($F36-$E36)*1440,0),"") | I36: =IF($G36="正常",$H36/60,"") | J36: =IF($G36="正常",ROUND($H36/30,0)/2,"") | K36: =IF($G36="正常",MIN($J36,12),"") | L36: =IF($G36="正常",MAX($J36-12,0),"")
A37: 宋龙元 | B37: 8/5 | C37: 三 | D37: 09:58 19:37 | E37: 0.41527778 | F37: 0.81736111 | G37: =IF($E37="","空卡",IF($F37="","单卡","正常")) | H37: =IF($G37="正常",ROUND(($F37-$E37)*1440,0),"") | I37: =IF($G37="正常",$H37/60,"") | J37: =IF($G37="正常",ROUND($H37/30,0)/2,"") | K37: =IF($G37="正常",MIN($J37,12),"") | L37: =IF($G37="正常",MAX($J37-12,0),"")
A38: 宋龙元 | B38: 8/6 | C38: 四 | D38: 08:59 19:01 | E38: 0.37430556 | F38: 0.79236111 | G38: =IF($E38="","空卡",IF($F38="","单卡","正常")) | H38: =IF($G38="正常",ROUND(($F38-$E38)*1440,0),"") | I38: =IF($G38="正常",$H38/60,"") | J38: =IF($G38="正常",ROUND($H38/30,0)/2,"") | K38: =IF($G38="正常",MIN($J38,12),"") | L38: =IF($G38="正常",MAX($J38-12,0),"")
A39: 宋龙元 | B39: 8/7 | C39: 五 | D39: 07:54 19:30 | E39: 0.32916667 | F39: 0.8125 | G39: =IF($E39="","空卡",IF($F39="","单卡","正常")) | H39: =IF($G39="正常",ROUND(($F39-$E39)*1440,0),"") | I39: =IF($G39="正常",$H39/60,"") | J39: =IF($G39="正常",ROUND($H39/30,0)/2,"") | K39: =IF($G39="正常",MIN($J39,12),"") | L39: =IF($G39="正常",MAX($J39-12,0),"")
A40: 宋龙元 | B40: 8/8 | C40: 六 | D40: 08:19 19:39 | E40: 0.34652778 | F40: 0.81875 | G40: =IF($E40="","空卡",IF($F40="","单卡","正常")) | H40: =IF($G40="正常",ROUND(($F40-$E40)*1440,0),"") | I40: =IF($G40="正常",$H40/60,"") | J40: =IF($G40="正常",ROUND($H40/30,0)/2,"") | K40: =IF($G40="正常",MIN($J40,12),"") | L40: =IF($G40="正常",MAX($J40-12,0),"")
...

Sheet 口径说明
A1: 2026年8月考勤核算口径与公式说明
A3: 一、核算口径（已用7月数据验证：45人中白班40人、加班41人完全吻合）
A4: 1. 上班天数：当日首末卡齐全（状态=正常）记 1 天；单卡、空卡不计，留白待人工补卡
A5: 2. 当日跨度(分钟) = ROUND((末卡 − 首卡) × 1440, 0) —— 先化成整数分钟再算，避免浮点误差
A6: 3. 取整工时 = ROUND(跨度分钟 ÷ 30, 0) ÷ 2 —— 四舍五入到 0.5 小时（30分钟为一个单位）
A7: 4. 白班 = MIN(取整工时, 12)：每天最多计 12 小时白班
A8: 5. 加班 = MAX(取整工时 − 12, 0)：超出 12 小时的部分才算加班
A9: 6. 月合计 = 白班合计 + 加班合计
A11: 二、每日明细公式（第2行为例，向下填充）
A12: 状态 G2 = IF($E2="","空卡",IF($F2="","单卡","正常"))
A13: 跨度(分) H2 = IF($G2="正常",ROUND(($F2-$E2)*1440,0),"")
A14: 跨度(h) I2 = IF($G2="正常",$H2/60,"")
... A34: 先 ROUND(×1440) 得到整数分钟，整数÷30 在边界处（如 735÷30=24.5）是精确值， ROUND 才稳定。
